Workbook

Sheet PF_stks
B1: Close | X1: Daily Returns | AS1: X = R_i - Avg(R_i)
A2: Date | B2: ADANIGREEN.NS | C2: AXISBANK.NS | D2: BAJAJ-AUTO.NS | E2: BAJAJFINSV.NS | F2: BDL.NS | G2: BEL.NS | H2: BHEL.NS | I2: BSE.NS | J2: CHOLAFIN.NS | K2: EICHERMOT.NS | L2: FEDERALBNK.NS | M2: HAL.NS | N2: HEROMOTOCO.NS | O2: M&M.NS | P2: MAFANG.NS | Q2: MAZDOCK.NS | R2: MON100.NS | S2: SBIN.NS | T2: SHRIRAMFIN.NS | U2: TVSMOTOR.NS | V2: ^BSESN | W2: ^NSEI | X2: ADANIGREEN.NS | Y2: AXISBANK.NS | Z2: BAJAJ-AUTO.NS | AA2: BAJAJFINSV.NS | AB2: BDL.NS | AC2: BEL.NS | AD2: BHEL.NS | AE2: BSE.NS | AF2: CHOLAFIN.NS | AG2: EICHERMOT.NS | AH2: FEDERALBNK.NS | AI2: HAL.NS | AJ2: HEROMOTOCO.NS | AK2: M&M.NS | AL2: MAFANG.NS | AM2: MAZDOCK.NS | AN2: MON100.NS | AO2: SBIN.NS | AP2: SHRIRAMFIN.NS | AQ2: TVSMOTOR.NS | AR2: ^NSEI | AS2: ADANIGREEN.NS | AT2: AXISBANK.NS | AU2: BAJAJ-AUTO.NS | AV2: BAJAJFINSV.NS | AW2: BDL.NS | AX2: BEL.NS | AY2: BHEL.NS | AZ2: BSE.NS | BA2: CHOLAFIN.NS | BB2: EICHERMOT.NS | BC2: FEDERALBNK.NS | BD2: HAL.NS | BE2: HEROMOTOCO.NS | BF2: M&M.NS | BG2: MAFANG.NS | BH2: MAZDOCK.NS | BI2: MON100.NS | BJ2: SBIN.NS | BK2: SHRIRAMFIN.NS | BL2: TVSMOTOR.NS | BM2: ^NSEI
A3: 45082 | B3: 987.84998 | C3: 948.33771 | D3: 4359.9771 | E3: 1456.5026 | F3: 565.76776 | G3: 112.59949 | H3: 85.006897 | I3: 187.84972 | J3: 1043.9912 | K3: 3547.3384 | L3: 124.84989 | M3: 1589.0297 | N3: 2599.3154 | O3: 1359.9648 | P3: 60.049999 | Q3: 479.92645 | R3: 116.22 | S3: 556.12311 | T3: 264.94904 | U3: 1279.8025 | V3: 62787.469 | W3: 18593.85 | X3: =X2 -> ADANIGREEN.NS | Y3: =Y2 -> AXISBANK.NS | Z3: =Z2 -> BAJAJ-AUTO.NS | AA3: =AA2 -> BAJAJFINSV.NS | AB3: =AB2 -> BDL.NS | AC3: =AC2 -> BEL.NS | AD3: =AD2 -> BHEL.NS | AE3: =AE2 -> BSE.NS | ... BM3: =BM2 -> ^NSEI
A4: 45083 | B4: 991.84998 | C4: 965.64185 | D4: 4374.9741 | E4: 1472.676 | F4: 587.18488 | G4: 114.93619 | H4: 83.26902 | I4: 184.29922 | J4: 1052.6533 | K4: 3578.0967 | L4: 123.72202 | M4: 1651.7487 | N4: 2630.2834 | O4: 1375.3635 | P4: 60.68 | Q4: 499.83209 | R4: 116.43 | S4: 554.37103 | T4: 266.45261 | U4: 1316.6732 | V4: 62792.879 | W4: 18599 | X4: =(B4-B3)/B3 -> 0.0040491979 | Y4: =(C4-C3)/C3 -> 0.01824681 | Z4: =(D4-D3)/D3 -> 0.0034397131 | AA4: =(E4-E3)/E3 -> 0.011104314 | AB4: =(F4-F3)/F3 -> 0.037854957 | AC4: =(G4-G3)/G3 -> 0.020752249 | AD4: =(H4-H3)/H3 -> -0.020443952 | AE4: =(I4-I3)/I3 -> -0.018900701 | ... AQ4: =(U4-U3)/U3 -> 0.028809701 | AR4: =(W4-W3)/W3 -> 0.00027699431 | AS4: =X4-Calculation!C$3 -> 0.002969142 | AT4: =Y4-Calculation!D$3 -> 0.017737891 | AU4: =Z4-Calculation!E$3 -> 0.0021344086 | AV4: =AA4-Calculation!F$3 -> 0.010782279 | AW4: =AB4-Calculation!G$3 -> 0.036408817 | AX4: =AC4-Calculation!H$3 -> 0.01878057 | AY4: =AD4-Calculation!I$3 -> -0.022872839 | AZ4: =AE4-Calculation!J$3 -> -0.023581092 | ... BM4: =AR4-Calculation!W$3 -> -6.8904289e-05
A5: 45084 | B5: 985.54999 | C5: 974.16931 | D5: 4425.4233 | E5: 1478.4664 | F5: 571.09113 | G5: 114.93619 | H5: 83.6166 | I5: 184.21779 | J5: 1068.5339 | K5: 3599.6321 | L5: 123.77106 | M5: 1688.0203 | N5: 2678.4556 | O5: 1370.6854 | P5: 61 | Q5: 500.87848 | R5: 116.26 | S5: 558.01727 | T5: 266.34857 | U5: 1331.995 | V5: 63142.961 | W5: 18726.4 | X5: =(B5-B4)/B4 -> -0.0063517547 | Y5: =(C5-C4)/C4 -> 0.0088308785 | Z5: =(D5-D4)/D4 -> 0.011531318 | AA5: =(E5-E4)/E4 -> 0.0039318935 | AB5: =(F5-F4)/F4 -> -0.027408318 | AC5: =(G5-G4)/G4 -> 0 | AD5: =(H5-H4)/H4 -> 0.0041741809 | AE5: =(I5-I4)/I4 -> -0.00044186923 | ... AQ5: =(U5-U4)/U4 -> 0.011636735 | AR5: =(W5-W4)/W4 -> 0.0068498516 | AS5: =X5-Calculation!C$3 -> -0.0074318106 | AT5: =Y5-Calculation!D$3 -> 0.0083219593 | AU5: =Z5-Calculation!E$3 -> 0.010226014 | AV5: =AA5-Calculation!F$3 -> 0.003609858 | AW5: =AB5-Calculation!G$3 -> -0.028854459 | AX5: =AC5-Calculation!H$3 -> -0.0019716796 | AY5: =AD5-Calculation!I$3 -> 0.0017452939 | AZ5: =AE5-Calculation!J$3 -> -0.0051222601 | ... BM5: =AR5-Calculation!W$3 -> 0.006503953
A6: 45085 | B6: 976 | C6: 959.55792 | D6: 4443.8442 | E6: 1464.9886 | F6: 568.82373 | G6: 114.44936 | H6: 83.715912 | I6: 182.01909 | J6: 1056.9845 | K6: 3532.0315 | L6: 123.67298 | M6: 1707.0632 | N6: 2684.6125 | O6: 1345.9791 | P6: 60.119999 | Q6: 490.14691 | R6: 114.64 | S6: 557.35431 | T6: 266.84027 | U6: 1310.8411 | V6: 62848.641 | W6: 18634.551 | X6: =(B6-B5)/B5 -> -0.0096900085 | Y6: =(C6-C5)/C5 -> -0.014998819 | Z6: =(D6-D5)/D5 -> 0.0041625167 | AA6: =(E6-E5)/E5 -> -0.0091160563 | AB6: =(F6-F5)/F5 -> -0.0039702859 | AC6: =(G6-G5)/G5 -> -0.0042356028 | AD6: =(H6-H5)/H5 -> 0.0011877047 | AE6: =(I6-I5)/I5 -> -0.011935329 | ... AQ6: =(U6-U5)/U5 -> -0.015881389 | AR6: =(W6-W5)/W5 -> -0.0049048193 | AS6: =X6-Calculation!C$3 -> -0.010770064 | AT6: =Y6-Calculation!D$3 -> -0.015507738 | AU6: =Z6-Calculation!E$3 -> 0.0028572121 | AV6: =AA6-Calculation!F$3 -> -0.0094380918 | AW6: =AB6-Calculation!G$3 -> -0.005416426 | AX6: =AC6-Calculation!H$3 -> -0.0062072824 | AY6: =AD6-Calculation!I$3 -> -0.0012411823 | AZ6: =AE6-Calculation!J$3 -> -0.01661572 | ... BM6: =AR6-Calculation!W$3 -> -0.0052507179
A7: 45086 | B7: 963.65002 | C7: 972.17456 | D7: 4390.8496 | E7: 1464.0901 | F7: 567.51758 | G7: 117.17552 | H7: 85.205521 | I7: 180.60216 | J7: 1061.0667 | K7: 3458.54 | L7: 122.69224 | M7: 1806.5139 | N7: 2625.303 | O7: 1335.8433 | P7: 60.650002 | Q7: 503.70129 | R7: 115.61 | S7: 548.073 | T7: 268.02228 | U7: 1320.6273 | V7: 62625.629 | W7: 18563.4 | X7: =(B7-B6)/B6 -> -0.012653664 | Y7: =(C7-C6)/C6 -> 0.013148386 | Z7: =(D7-D6)/D6 -> -0.011925402 | AA7: =(E7-E6)/E6 -> -0.000613356 | AB7: =(F7-F6)/F6 -> -0.0022962339 | AC7: =(G7-G6)/G6 -> 0.023819775 | AD7: =(H7-H6)/H6 -> 0.017793616 | AE7: =(I7-I6)/I6 -> -0.0077845195 | ... AQ7: =(U7-U6)/U6 -> 0.0074656304 | AR7: =(W7-W6)/W6 -> -0.0038181973 | AS7: =X7-Calculation!C$3 -> -0.013733719 | AT7: =Y7-Calculation!D$3 -> 0.012639467 | AU7: =Z7-Calculation!E$3 -> -0.013230707 | AV7: =AA7-Calculation!F$3 -> -0.00093539147 | AW7: =AB7-Calculation!G$3 -> -0.0037423741 | AX7: =AC7-Calculation!H$3 -> 0.021848096 | AY7: =AD7-Calculation!I$3 -> 0.015364729 | AZ7: =AE7-Calculation!J$3 -> -0.01246491 | ... BM7: =AR7-Calculation!W$3 -> -0.0041640959
A8: 45089 | B8: 961.09998 | C8: 971.62598 | D8: 4415.1479 | E8: 1463.5909 | F8: 561.89832 | G8: 115.95849 | H8: 85.205521 | I8: 185.79759 | J8: 1068.4344 | K8: 3467.5215 | L8: 122.79031 | M8: 1783.8411 | N8: 2653.4636 | O8: 1346.3204 | P8: 61.380001 | Q8: 508.83585 | R8: 116.86 | S8: 548.0257 | T8: 274.66989 | U8: 1324.1858 | V8: 62724.711 | W8: 18601.5 | X8: =(B8-B7)/B7 -> -0.0026462396 | Y8: =(C8-C7)/C7 -> -0.00056428548 | Z8: =(D8-D7)/D7 -> 0.0055338584 | AA8: =(E8-E7)/E7 -> -0.00034092541 | AB8: =(F8-F7)/F7 -> -0.0099014778 | AC8: =(G8-G7)/G7 -> -0.010386413 | AD8: =(H8-H7)/H7 -> 0 | AE8: =(I8-I7)/I7 -> 0.02876729 | ... AQ8: =(U8-U7)/U7 -> 0.0026945313 | AR8: =(W8-W7)/W7 -> 0.0020524047 | AS8: =X8-Calculation!C$3 -> -0.0037262954 | AT8: =Y8-Calculation!D$3 -> -0.0010732047 | AU8: =Z8-Calculation!E$3 -> 0.0042285538 | AV8: =AA8-Calculation!F$3 -> -0.00066296088 | AW8: =AB8-Calculation!G$3 -> -0.011347618 | AX8: =AC8-Calculation!H$3 -> -0.012358093 | AY8: =AD8-Calculation!I$3 -> -0.002428887 | AZ8: =AE8-Calculation!J$3 -> 0.024086899 | ... BM8: =AR8-Calculation!W$3 -> 0.0017065061
A9: 45090 | B9: 955.29999 | C9: 983.24518 | D9: 4402.4668 | E9: 1483.7576 | F9: 550.98022 | G9: 118.87936 | H9: 84.510361 | I9: 183.37088 | J9: 1097.0096 | K9: 3469.5012 | L9: 122.15282 | M9: 1761.1683 | N9: 2673.4299 | O9: 1338.2799 | P9: 62.330002 | Q9: 505.16138 | R9: 118.73 | S9: 545.89471 | T9: 272.97726 | U9: 1330.6111 | V9: 63143.16 | W9: 18716.15 | X9: =(B9-B8)/B8 -> -0.0060347393 | Y9: =(C9-C8)/C8 -> 0.011958513 | Z9: =(D9-D8)/D8 -> -0.0028721919 | AA9: =(E9-E8)/E8 -> 0.013778868 | AB9: =(F9-F8)/F8 -> -0.019430724 | AC9: =(G9-G8)/G8 -> 0.02518891 | AD9: =(H9-H8)/H8 -> -0.0081586253 | AE9: =(I9-I8)/I8 -> -0.013061052 | ... AQ9: =(U9-U8)/U8 -> 0.0048522594 | AR9: =(W9-W8)/W8 -> 0.0061635024 | AS9: =X9-Calculation!C$3 -> -0.0071147951 | AT9: =Y9-Calculation!D$3 -> 0.011449594 | AU9: =Z9-Calculation!E$3 -> -0.0041774965 | AV9: =AA9-Calculation!F$3 -> 0.013456832 | AW9: =AB9-Calculation!G$3 -> -0.020876864 | AX9: =AC9-Calculation!H$3 -> 0.02321723 | AY9: =AD9-Calculation!I$3 -> -0.010587512 | AZ9: =AE9-Calculation!J$3 -> -0.017741443 | ... BM9: =AR9-Calculation!W$3 -> 0.0058176038
A10: 45091 | B10: 957.65002 | C10: 975.11676 | D10: 4378.6299 | E10: 1477.9672 | F10: 544.81879 | G10: 118.19782 | H10: 83.26902 | I10: 185.83017 | J10: 1094.5205 | K10: 3449.6074 | L10: 122.00571 | M10: 1798.1417 | N10: 2654.5503 | O10: 1343.6401 | P10: 62.68 | Q10: 501.43823 | R10: 119.01 | S10: 546.03674 | T10: 266.24454 | U10: 1330.3639 | V10: 63228.512 | W10: 18755.9 | X10: =(B10-B9)/B9 -> 0.0024599986 | Y10: =(C10-C9)/C9 -> -0.0082669289 | Z10: =(D10-D9)/D9 -> -0.0054144449 | AA10: =(E10-E9)/E9 -> -0.0039025279 | AB10: =(F10-F9)/F9 -> -0.011182684 | AC10: =(G10-G9)/G9 -> -0.0057329871 | AD10: =(H10-H9)/H9 -> -0.014688621 | AE10: =(I10-I9)/I9 -> 0.01341156 | ... AQ10: =(U10-U9)/U9 -> -0.00018577358 | AR10: =(W10-W9)/W9 -> 0.0021238342 | AS10: =X10-Calculation!C$3 -> 0.0013799427 | AT10: =Y10-Calculation!D$3 -> -0.0087758481 | AU10: =Z10-Calculation!E$3 -> -0.0067197495 | AV10: =AA10-Calculation!F$3 -> -0.0042245633 | AW10: =AB10-Calculation!G$3 -> -0.012628825 | AX10: =AC10-Calculation!H$3 -> -0.0077046667 | AY10: =AD10-Calculation!I$3 -> -0.017117508 | AZ10: =AE10-Calculation!J$3 -> 0.0087311691 | ... BM10: =AR10-Calculation!W$3 -> 0.0017779356
A11: 45092 | B11: 962.59998 | C11: 974.56824 | D11: 4370.623 | E11: 1472.2766 | F11: 557.19098 | G11: 118.73332 | H11: 83.964172 | I11: 186.95393 | J11: 1108.0614 | K11: 3413.5374 | L11: 119.70094 | M11: 1794.2701 | N11: 2574.3691 | O11: 1357.3821 | P11: 63.610001 | Q11: 513.24048 | R11: 118.91 | S11: 536.51862 | T11: 267.45493 | U11: 1317.5135 | V11: 62917.629 | W11: 18688.1 | X11: =(B11-B10)/B10 -> 0.0051688519 | Y11: =(C11-C10)/C10 -> -0.00056252028 | Z11: =(D11-D10)/D10 -> -0.0018286167 | AA11: =(E11-E10)/E10 -> -0.0038502559 | AB11: =(F11-F10)/F10 -> 0.022708821 | AC11: =(G11-G10)/G10 -> 0.0045305367 | AD11: =(H11-H10)/H10 -> 0.0083482702 | AE11: =(I11-I10)/I10 -> 0.0060472637 | ... AQ11: =(U11-U10)/U10 -> -0.0096592683 | AR11: =(W11-W10)/W10 -> -0.0036149041 | AS11: =X11-Calculation!C$3 -> 0.0040887961 | AT11: =Y11-Calculation!D$3 -> -0.0010714395 | AU11: =Z11-Calculation!E$3 -> -0.0031339213 | AV11: =AA11-Calculation!F$3 -> -0.0041722914 | AW11: =AB11-Calculation!G$3 -> 0.021262681 | AX11: =AC11-Calculation!H$3 -> 0.0025588571 | AY11: =AD11-Calculation!I$3 -> 0.0059193832 | AZ11: =AE11-Calculation!J$3 -> 0.0013668728 | ... BM11: =AR11-Calculation!W$3 -> -0.0039608027
A12: 45093 | B12: 975.04999 | C12: 978.95654 | D12: 4296.9399 | E12: 1506.1208 | F12: 581.17133 | G12: 121.89758 | H12: 86.148933 | I12: 186.40019 | J12: 1121.7516 | K12: 3417.5933 | L12: 121.36822 | M12: 1860.6188 | N12: 2564.4084 | O12: 1368.2002 | P12: 64.550003 | Q12: 577.99475 | R12: 120.81 | S12: 541.01721 | T12: 268.85529 | U12: 1337.2833 | V12: 63384.578 | W12: 18826 | X12: =(B12-B11)/B11 -> 0.012933734 | Y12: =(C12-C11)/C11 -> 0.0045028203 | Z12: =(D12-D11)/D11 -> -0.016858719 | AA12: =(E12-E11)/E11 -> 0.02298769 | AB12: =(F12-F11)/F11 -> 0.043037931 | AC12: =(G12-G11)/G11 -> 0.026650086 | AD12: =(H12-H11)/H11 -> 0.026020158 | AE12: =(I12-I11)/I11 -> -0.0029619139 | ... AQ12: =(U12-U11)/U11 -> 0.015005368 | AR12: =(W12-W11)/W11 -> 0.0073790484 | AS12: =X12-Calculation!C$3 -> 0.011853678 | AT12: =Y12-Calculation!D$3 -> 0.0039939011 | AU12: =Z12-Calculation!E$3 -> -0.018164024 | AV12: =AA12-Calculation!F$3 -> 0.022665654 | AW12: =AB12-Calculation!G$3 -> 0.04159179 | AX12: =AC12-Calculation!H$3 -> 0.024678406 | AY12: =AD12-Calculation!I$3 -> 0.023591271 | AZ12: =AE12-Calculation!J$3 -> -0.0076423048 | ... BM12: =AR12-Calculation!W$3 -> 0.0070331497
A13: 45096 | B13: 960.34998 | C13: 963.09863 | D13: 4255.6543 | E13: 1539.4161 | F13: 589.6001 | G13: 121.55682 | H13: 86.744774 | I13: 185.27643 | J13: 1127.3273 | K13: 3376.7917 | L13: 120.73073 | M13: 1884.1869 | N13: 2519.6316 | O13: 1366.9332 | P13: 63.599998 | Q13: 592.83881 | R13: 120.18 | S13: 538.74426 | T13: 281.96716 | U13: 1322.5547 | V13: 63168.301 | W13: 18755.449 | X13: =(B13-B12)/B12 -> -0.015076163 | Y13: =(C13-C12)/C12 -> -0.016198789 | Z13: =(D13-D12)/D12 -> -0.0096081502 | AA13: =(E13-E12)/E12 -> 0.022106651 | AB13: =(F13-F12)/F12 -> 0.014503076 | AC13: =(G13-G12)/G12 -> -0.0027954557 | AD13: =(H13-H12)/H12 -> 0.0069163997 | AE13: =(I13-I12)/I12 -> -0.0060287708 | ... AQ13: =(U13-U12)/U12 -> -0.01101385 | AR13: =(W13-W12)/W12 -> -0.0037475184 | AS13: =X13-Calculation!C$3 -> -0.016156219 | AT13: =Y13-Calculation!D$3 -> -0.016707708 | AU13: =Z13-Calculation!E$3 -> -0.010913455 | AV13: =AA13-Calculation!F$3 -> 0.021784616 | AW13: =AB13-Calculation!G$3 -> 0.013056936 | AX13: =AC13-Calculation!H$3 -> -0.0047671354 | AY13: =AD13-Calculation!I$3 -> 0.0044875127 | AZ13: =AE13-Calculation!J$3 -> -0.010709162 | ... BM13: =AR13-Calculation!W$3 -> -0.004093417
A14: 45097 | B14: 961.70001 | C14: 972.27423 | D14: 4315.499 | E14: 1518.5505 | F14: 597.83179 | G14: 121.84892 | H14: 87.340614 | I14: 186.28618 | J14: 1117.0225 | K14: 3439.9985 | L14: 121.02496 | M14: 1862.5544 | N14: 2536.021 | O14: 1360.988 | P14: 63.419998 | Q14: 636.03265 | R14: 119.69 | S14: 537.37103 | T14: 299.19388 | U14: 1328.3375 | V14: 63327.699 | W14: 18816.699 | X14: =(B14-B13)/B13 -> 0.0014057757 | Y14: =(C14-C13)/C13 -> 0.0095271635 | Z14: =(D14-D13)/D13 -> 0.014062403 | AA14: =(E14-E13)/E13 -> -0.01355423 | AB14: =(F14-F13)/F13 -> 0.013961479 | AC14: =(G14-G13)/G13 -> 0.0024030461 | AD14: =(H14-H13)/H13 -> 0.0068688917 | AE14: =(I14-I13)/I13 -> 0.0054499667 | ... AQ14: =(U14-U13)/U13 -> 0.0043724747 | AR14: =(W14-W13)/W13 -> 0.0032657176 | AS14: =X14-Calculation!C$3 -> 0.00032571981 | AT14: =Y14-Calculation!D$3 -> 0.0090182443 | AU14: =Z14-Calculation!E$3 -> 0.012757099 | AV14: =AA14-Calculation!F$3 -> -0.013876266 | AW14: =AB14-Calculation!G$3 -> 0.012515339 | AX14: =AC14-Calculation!H$3 -> 0.00043136646 | AY14: =AD14-Calculation!I$3 -> 0.0044400047 | AZ14: =AE14-Calculation!J$3 -> 0.00076957584 | ... BM14: =AR14-Calculation!W$3 -> 0.002919819
A15: 45098 | B15: 977 | C15: 963.44769 | D15: 4304.5298 | E15: 1516.7535 | F15: 586.47015 | G15: 119.5609 | H15: 86.297897 | I15: 186.3676 | J15: 1129.4181 | K15: 3448.0623 | L15: 121.07398 | M15: 1848.8348 | N15: 2556.7114 | O15: 1339.3518 | P15: 63.080002 | Q15: 593.81219 | R15: 119.92 | S15: 536.37659 | T15: 332.70728 | U15: 1335.3558 | V15: 63523.148 | W15: 18856.85 | X15: =(B15-B14)/B14 -> 0.015909314 | Y15: =(C15-C14)/C14 -> -0.0090782393 | Z15: =(D15-D14)/D14 -> -0.0025418238 | AA15: =(E15-E14)/E14 -> -0.0011833634 | AB15: =(F15-F14)/F14 -> -0.019004733 | AC15: =(G15-G14)/G14 -> -0.018777555 | AD15: =(H15-H14)/H14 -> -0.011938512 | AE15: =(I15-I14)/I14 -> 0.00043707429 | ... AQ15: =(U15-U14)/U14 -> 0.0052835295 | AR15: =(W15-W14)/W14 -> 0.0021337637 | AS15: =X15-Calculation!C$3 -> 0.014829258 | AT15: =Y15-Calculation!D$3 -> -0.0095871585 | AU15: =Z15-Calculation!E$3 -> -0.0038471284 | AV15: =AA15-Calculation!F$3 -> -0.0015053988 | AW15: =AB15-Calculation!G$3 -> -0.020450873 | AX15: =AC15-Calculation!H$3 -> -0.020749235 | AY15: =AD15-Calculation!I$3 -> -0.014367399 | AZ15: =AE15-Calculation!J$3 -> -0.0042433166 | ... BM15: =AR15-Calculation!W$3 -> 0.0017878651
... A737: 46178 | B737: 1525.7 | C737: 1272.3 | D737: 10342 | E737: 1703.2 | F737: 1207.4 | G737: 408.20001 | H737: 386.95001 | I737: 3880 | J737: 1503.2 | K737: 7070 | L737: 304.14999 | M737: 4216.8999 | N737: 4835 | O737: 3040.5 | P737: 206.92 | Q737: 2423.1001 | R737: 342.54999 | S737: 977.70001 | T737: 923.29999 | U737: 3383.8999 | V737: 74243.344 | W737: 23366.699 | X737: =(B737-B736)/B736 -> 0.071945408 | Y737: =(C737-C736)/C736 -> 0.015159977 | Z737: =(D737-D736)/D736 -> -0.0019301293 | AA737: =(E737-E736)/E736 -> -0.0038601576 | AB737: =(F737-F736)/F736 -> -0.0044525265 | AC737: =(G737-G736)/G736 -> -0.0041473084 | AD737: =(H737-H736)/H736 -> -0.0057810892 | AE737: =(I737-I736)/I736 -> -0.038032406 | ... AQ737: =(U737-U736)/U736 -> 0.0063642832 | AR737: =(W737-W736)/W736 -> -0.0021289029 | AS737: =X737-Calculation!C$3 -> 0.070865352 | AT737: =Y737-Calculation!D$3 -> 0.014651058 | AU737: =Z737-Calculation!E$3 -> -0.0032354339 | AV737: =AA737-Calculation!F$3 -> -0.0041821931 | AW737: =AB737-Calculation!G$3 -> -0.0058986667 | AX737: =AC737-Calculation!H$3 -> -0.006118988 | AY737: =AD737-Calculation!I$3 -> -0.0082099762 | AZ737: =AE737-Calculation!J$3 -> -0.042712797 | ... BM737: =AR737-Calculation!W$3 -> -0.0024748015

Sheet Calculation
C2: ADANIGREEN.NS | D2: AXISBANK.NS | E2: BAJAJ-AUTO.NS | F2: BAJAJFINSV.NS | G2: BDL.NS | H2: BEL.NS | I2: BHEL.NS | J2: BSE.NS | K2: CHOLAFIN.NS | L2: EICHERMOT.NS | M2: FEDERALBNK.NS | N2: HAL.NS | O2: HEROMOTOCO.NS | P2: M&M.NS | Q2: MAFANG.NS | R2: MAZDOCK.NS | S2: MON100.NS | T2: SBIN.NS | U2: SHRIRAMFIN.NS | V2: TVSMOTOR.NS | W2: ^NSEI | X2: Total PF
A3: Avg Return (Daily) | B3: E (r) | C3: =AVERAGE(PF_stks!X4:X737) -> 0.0010800559 | D3: =AVERAGE(PF_stks!Y4:Y737) -> 0.00050891923 | E3: =AVERAGE(PF_stks!Z4:Z737) -> 0.0013053046 | F3: =AVERAGE(PF_stks!AA4:AA737) -> 0.00032203547 | G3: =AVERAGE(PF_stks!AB4:AB737) -> 0.0014461401 | H3: =AVERAGE(PF_stks!AC4:AC737) -> 0.0019716796 | I3: =AVERAGE(PF_stks!AD4:AD737) -> 0.002428887 | J3: =AVERAGE(PF_stks!AE4:AE737) -> 0.0046803909 | ... W3: =AVERAGE(PF_stks!AR4:AR737) -> 0.0003458986 | X3: =AVERAGE(C3:W3) -> 0.0014979972
A4: Avg Return (Annual) | B4: E (r_A) | C4: =EXP(C3*252)-1 -> 0.31281551 | D4: =EXP(D3*252)-1 -> 0.1368345 | E4: =EXP(E3*252)-1 -> 0.38948997 | F4: =EXP(F3*252)-1 -> 0.084536752 | G4: =EXP(G3*252)-1 -> 0.43968929 | H4: =EXP(H3*252)-1 -> 0.64355776 | I4: =EXP(I3*252)-1 -> 0.8442626 | J4: =EXP(J3*252)-1 -> 2.2526124 | ... W4: =EXP(W3*252)-1 -> 0.091078272 | X4: =AVERAGE(C4:W4) -> 0.50660818
A5: Std Dev (Daily) | B5: σ (daily) | C5: =_xlfn.STDEV.S(PF_stks!X4:X737) -> 0.031468093 | D5: =_xlfn.STDEV.S(PF_stks!Y4:Y737) -> 0.01473849 | E5: =_xlfn.STDEV.S(PF_stks!Z4:Z737) -> 0.015969173 | F5: =_xlfn.STDEV.S(PF_stks!AA4:AA737) -> 0.014776767 | G5: =_xlfn.STDEV.S(PF_stks!AB4:AB737) -> 0.028799293 | H5: =_xlfn.STDEV.S(PF_stks!AC4:AC737) -> 0.020631445 | I5: =_xlfn.STDEV.S(PF_stks!AD4:AD737) -> 0.026787336 | J5: =_xlfn.STDEV.S(PF_stks!AE4:AE737) -> 0.033428357 | ... W5: =_xlfn.STDEV.S(PF_stks!AR4:AR737) -> 0.0083112521
A6: Std Dev (Annual) | B6: σ (annual) | C6: =C5*SQRT(252) -> 0.4995405 | D6: =D5*SQRT(252) -> 0.23396628 | E6: =E5*SQRT(252) -> 0.25350276 | F6: =F5*SQRT(252) -> 0.23457391 | G6: =G5*SQRT(252) -> 0.45717461 | H6: =H5*SQRT(252) -> 0.32751404 | I6: =I5*SQRT(252) -> 0.42523577 | J6: =J5*SQRT(252) -> 0.53065872 | ... W6: =W5*SQRT(252) -> 0.13193704
A7: Variance (Daily) | B7: σ^2 (daily) | C7: =_xlfn.VAR.S(PF_stks!X4:X737) -> 0.0009902409 | D7: =_xlfn.VAR.S(PF_stks!Y4:Y737) -> 0.00021722309 | E7: =_xlfn.VAR.S(PF_stks!Z4:Z737) -> 0.00025501447 | F7: =_xlfn.VAR.S(PF_stks!AA4:AA737) -> 0.00021835284 | G7: =_xlfn.VAR.S(PF_stks!AB4:AB737) -> 0.0008293993 | H7: =_xlfn.VAR.S(PF_stks!AC4:AC737) -> 0.00042565653 | I7: =_xlfn.VAR.S(PF_stks!AD4:AD737) -> 0.00071756135 | J7: =_xlfn.VAR.S(PF_stks!AE4:AE737) -> 0.0011174551 | ... W7: =_xlfn.VAR.S(PF_stks!AR4:AR737) -> 6.9076912e-05
A8: Variance (Annual) | B8: σ^2 (annual) | C8: =C7*252 -> 0.24954071 | D8: =D7*252 -> 0.054740219 | E8: =E7*252 -> 0.064263647 | F8: =F7*252 -> 0.055024917 | G8: =G7*252 -> 0.20900862 | H8: =H7*252 -> 0.10726545 | I8: =I7*252 -> 0.18082546 | J8: =J7*252 -> 0.28159867 | ... W8: =W7*252 -> 0.017407382
A9: Weight | B9: w | C9: 0.05 | D9: 0.05 | E9: 0.05 | F9: 0.05 | G9: 0.05 | H9: 0.05 | I9: 0.05 | J9: 0.05 | K9: 0.05 | L9: 0.05 | M9: 0.05 | N9: 0.05 | O9: 0.05 | P9: 0.05 | Q9: 0.05 | R9: 0.05 | S9: 0.05 | T9: 0.05 | U9: 0.05 | V9: 0.05 | W9: 0 | X9: =SUM(C9:W9) -> 1
A10: N-observation | B10: n | C10: =COUNT(PF_stks!X4:X737) -> 734 | D10: =COUNT(PF_stks!Y4:Y737) -> 734 | E10: =COUNT(PF_stks!Z4:Z737) -> 734 | F10: =COUNT(PF_stks!AA4:AA737) -> 734 | G10: =COUNT(PF_stks!AB4:AB737) -> 734 | H10: =COUNT(PF_stks!AC4:AC737) -> 734 | I10: =COUNT(PF_stks!AD4:AD737) -> 734 | J10: =COUNT(PF_stks!AE4:AE737) -> 734 | ... W10: =COUNT(PF_stks!AR4:AR737) -> 734
A12: Risk Free Rate | B12: R_f (Annual) | C12: 0.0701
A13: Risk Free Rate | B13: R_f (Daily) | C13: =(1+C12)^(1/252)-1 -> 0.00026889369 | D13: =C12/252 -> 0.0002781746
C16: Hedge Ratio β = COV(stock returns,index returns)/VAR(index returns)
C17: ADANIGREEN.NS | D17: AXISBANK.NS | E17: BAJAJ-AUTO.NS | F17: BAJAJFINSV.NS | G17: BDL.NS | H17: BEL.NS | I17: BHEL.NS | J17: BSE.NS | K17: CHOLAFIN.NS | L17: EICHERMOT.NS | M17: FEDERALBNK.NS | N17: HAL.NS | O17: HEROMOTOCO.NS | P17: M&M.NS | Q17: MAFANG.NS | R17: MAZDOCK.NS | S17: MON100.NS | T17: SBIN.NS | U17: SHRIRAMFIN.NS | V17: TVSMOTOR.NS
B18: ^NSEI (COV.S) | C18: =_xlfn.COVARIANCE.S(PF_stks!X4:X737,PF_stks!$AR$4:$AR$737)/Calculation!$W$7 -> 1.7210877 | D18: =_xlfn.COVARIANCE.S(PF_stks!Y4:Y737,PF_stks!$AR$4:$AR$737)/Calculation!$W$7 -> 1.1159152 | E18: =_xlfn.COVARIANCE.S(PF_stks!Z4:Z737,PF_stks!$AR$4:$AR$737)/Calculation!$W$7 -> 0.8896131 | F18: =_xlfn.COVARIANCE.S(PF_stks!AA4:AA737,PF_stks!$AR$4:$AR$737)/Calculation!$W$7 -> 1.1308339 | G18: =_xlfn.COVARIANCE.S(PF_stks!AB4:AB737,PF_stks!$AR$4:$AR$737)/Calculation!$W$7 -> 1.2409404 | H18: =_xlfn.COVARIANCE.S(PF_stks!AC4:AC737,PF_stks!$AR$4:$AR$737)/Calculation!$W$7 -> 1.3136985 | I18: =_xlfn.COVARIANCE.S(PF_stks!AD4:AD737,PF_stks!$AR$4:$AR$737)/Calculation!$W$7 -> 1.6484094 | J18: =_xlfn.COVARIANCE.S(PF_stks!AE4:AE737,PF_stks!$AR$4:$AR$737)/Calculation!$W$7 -> 1.2731254 | ... V18: =_xlfn.COVARIANCE.S(PF_stks!AQ4:AQ737,PF_stks!$AR$4:$AR$737)/Calculation!$W$7 -> 1.0699456
B19: ^NSEI (COV.P) | C19: =_xlfn.COVARIANCE.P(PF_stks!X4:X737,PF_stks!$AR$4:$AR$737)/_xlfn.VAR.P(PF_stks!$AR$4:$AR$737) -> 1.7210877 | D19: =_xlfn.COVARIANCE.P(PF_stks!Y4:Y737,PF_stks!$AR$4:$AR$737)/_xlfn.VAR.P(PF_stks!$AR$4:$AR$737) -> 1.1159152 | E19: =_xlfn.COVARIANCE.P(PF_stks!Z4:Z737,PF_stks!$AR$4:$AR$737)/_xlfn.VAR.P(PF_stks!$AR$4:$AR$737) -> 0.8896131 | F19: =_xlfn.COVARIANCE.P(PF_stks!AA4:AA737,PF_stks!$AR$4:$AR$737)/_xlfn.VAR.P(PF_stks!$AR$4:$AR$737) -> 1.1308339 | G19: =_xlfn.COVARIANCE.P(PF_stks!AB4:AB737,PF_stks!$AR$4:$AR$737)/_xlfn.VAR.P(PF_stks!$AR$4:$AR$737) -> 1.2409404 | H19: =_xlfn.COVARIANCE.P(PF_stks!AC4:AC737,PF_stks!$AR$4:$AR$737)/_xlfn.VAR.P(PF_stks!$AR$4:$AR$737) -> 1.3136985 | I19: =_xlfn.COVARIANCE.P(PF_stks!AD4:AD737,PF_stks!$AR$4:$AR$737)/_xlfn.VAR.P(PF_stks!$AR$4:$AR$737) -> 1.6484094 | J19: =_xlfn.COVARIANCE.P(PF_stks!AE4:AE737,PF_stks!$AR$4:$AR$737)/_xlfn.VAR.P(PF_stks!$AR$4:$AR$737) -> 1.2731254 | ... V19: =_xlfn.COVARIANCE.P(PF_stks!AQ4:AQ737,PF_stks!$AR$4:$AR$737)/_xlfn.VAR.P(PF_stks!$AR$4:$AR$737) -> 1.0699456
C21: Expected Returns Daily E(r_i) = r_f + [β * ( E(r_s) - r_f )]
C22: ADANIGREEN.NS | D22: AXISBANK.NS | E22: BAJAJ-AUTO.NS | F22: BAJAJFINSV.NS | G22: BDL.NS | H22: BEL.NS | I22: BHEL.NS | J22: BSE.NS | K22: CHOLAFIN.NS | L22: EICHERMOT.NS | M22: FEDERALBNK.NS | N22: HAL.NS | O22: HEROMOTOCO.NS | P22: M&M.NS | Q22: MAFANG.NS | R22: MAZDOCK.NS | S22: MON100.NS | T22: SBIN.NS | U22: SHRIRAMFIN.NS | V22: TVSMOTOR.NS
A23: Exp Returns (Daily) | B23: R_i (r_f=0.0269%) | C23: =$C$13+(C18*(C3-$C$13)) -> 0.0016649749 | D23: =$C$13+(D18*(D3-$C$13)) -> 0.00053674185 | E23: =$C$13+(E18*(E3-$C$13)) -> 0.0011908984 | F23: =$C$13+(F18*(F3-$C$13)) -> 0.00032898822 | G23: =$C$13+(G18*(G3-$C$13)) -> 0.0017297863 | H23: =$C$13+(H18*(H3-$C$13)) -> 0.002505841 | I23: =$C$13+(I18*(I3-$C$13)) -> 0.003829447 | J23: =$C$13+(J18*(J3-$C$13)) -> 0.0058852828 | ... V23: =$C$13+(V18*(V3-$C$13)) -> 0.0015507035
A24: Exp Returns (Daily) | B24: R_i (r_f=0.02781%) | C24: =$D$13+(C18*(C3-$D$13)) -> 0.0016582825 | D24: =$D$13+(D18*(D3-$D$13)) -> 0.00053566605 | E24: =$D$13+(E18*(E3-$D$13)) -> 0.0011919229 | F24: =$D$13+(F18*(F3-$D$13)) -> 0.00032777396 | G24: =$D$13+(G18*(G3-$D$13)) -> 0.0017275502 | H24: =$D$13+(H18*(H3-$D$13)) -> 0.0025029296 | I24: =$D$13+(I18*(I3-$D$13)) -> 0.0038234291 | J24: =$D$13+(J18*(J3-$D$13)) -> 0.0058827479 | ... V24: =$D$13+(V18*(V3-$D$13)) -> 0.0015500544
C26: Covariance Matrix Σ=X'X/(n-1)
C27: ADANIGREEN.NS | D27: AXISBANK.NS | E27: BAJAJ-AUTO.NS | F27: BAJAJFINSV.NS | G27: BDL.NS | H27: BEL.NS | I27: BHEL.NS | J27: BSE.NS | K27: CHOLAFIN.NS | L27: EICHERMOT.NS | M27: FEDERALBNK.NS | N27: HAL.NS | O27: HEROMOTOCO.NS | P27: M&M.NS | Q27: MAFANG.NS | R27: MAZDOCK.NS | S27: MON100.NS | T27: SBIN.NS | U27: SHRIRAMFIN.NS | V27: TVSMOTOR.NS | W27: ^NSEI
B28: {=TRANSPOSE(C27:W27)} -> ADANIGREEN.NS | C28: {=MMULT(TRANSPOSE(PF_stks!AS4:BM737),PF_stks!AS4:BM737)/733} -> 0.0009902409 | D28: 0.00013539385 | E28: 0.00012328423 | F28: 0.00013727421 | G28: 0.00022658088 | H28: 0.00023258727 | I28: 0.00029903878 | J28: 0.00025799368 | K28: 0.00016930572 | L28: 0.00013580208 | M28: 0.00013298746 | N28: 0.00023592716 | O28: 0.00012704605 | P28: 0.00014546867 | Q28: 4.8022748e-05 | R28: 0.0002899962 | S28: 8.6647181e-05 | T28: 0.00016878589 | U28: 0.00021761183 | V28: 0.00015577431 | W28: 0.00011888742
B29: AXISBANK.NS | C29: 0.00013539385 | D29: 0.00021722309 | E29: 6.8757525e-05 | F29: 9.8277292e-05 | G29: 8.225993e-05 | H29: 9.3643616e-05 | I29: 0.00012248037 | J29: 9.3597403e-05 | K29: 0.00012089666 | L29: 8.7649373e-05 | M29: 8.5182389e-05 | N29: 0.0001011663 | O29: 6.3269554e-05 | P29: 8.8721653e-05 | Q29: 1.6606027e-05 | R29: 0.00013257864 | S29: 3.820464e-05 | T29: 0.00011417541 | U29: 0.00016038867 | V29: 9.1744334e-05 | W29: 7.708398e-05
B30: BAJAJ-AUTO.NS | C30: 0.00012328423 | D30: 6.8757525e-05 | E30: 0.00025501447 | F30: 7.1296308e-05 | G30: 0.00010021514 | H30: 8.2818873e-05 | I30: 0.00012210702 | J30: 0.0001132721 | K30: 0.00010768479 | L30: 0.00010866322 | M30: 6.614743e-05 | N30: 9.5450516e-05 | O30: 0.00014541174 | P30: 0.00012177026 | Q30: 2.0993219e-05 | R30: 0.00011665432 | S30: 4.9141482e-05 | T30: 5.9561289e-05 | U30: 0.00012621707 | V30: 0.00013708992 | W30: 6.1451726e-05
B31: BAJAJFINSV.NS | C31: 0.00013727421 | D31: 9.8277292e-05 | E31: 7.1296308e-05 | F31: 0.00021835284 | G31: 7.0899602e-05 | H31: 8.0655377e-05 | I31: 0.00010792578 | J31: 9.4660529e-05 | K31: 0.00016207753 | L31: 8.2670571e-05 | M31: 7.3847929e-05 | N31: 8.4406564e-05 | O31: 8.2055292e-05 | P31: 0.00011359013 | Q31: 1.9884546e-05 | R31: 7.9728302e-05 | S31: 5.1777297e-05 | T31: 9.1850116e-05 | U31: 0.00016591692 | V31: 9.1002388e-05 | W31: 7.8114511e-05
B32: BDL.NS | C32: 0.00022658088 | D32: 8.225993e-05 | E32: 0.00010021514 | F32: 7.0899602e-05 | G32: 0.0008293993 | H32: 0.00037342764 | I32: 0.00034885116 | J32: 0.0002516801 | K32: 0.00012538019 | L32: 0.00010217958 | M32: 9.4487363e-05 | N32: 0.000426153 | O32: 9.5459928e-05 | P32: 0.00011536142 | Q32: 5.5067169e-05 | R32: 0.00057799882 | S32: 9.5597514e-05 | T32: 0.00014328343 | U32: 0.00018106204 | V32: 0.00012610932 | W32: 8.5720328e-05
B33: BEL.NS | C33: 0.00023258727 | D33: 9.3643616e-05 | E33: 8.2818873e-05 | F33: 8.0655377e-05 | G33: 0.00037342764 | H33: 0.00042565653 | I33: 0.00035163589 | J33: 0.00019598511 | K33: 0.00012643018 | L33: 9.2397382e-05 | M33: 0.00011726531 | N33: 0.00034444793 | O33: 7.7897508e-05 | P33: 0.00012466323 | Q33: 5.7651277e-05 | R33: 0.00037927598 | S33: 7.5614856e-05 | T33: 0.00015447995 | U33: 0.00018165495 | V33: 0.00010422338 | W33: 9.0746235e-05
B34: BHEL.NS | C34: 0.00029903878 | D34: 0.00012248037 | E34: 0.00012210702 | F34: 0.00010792578 | G34: 0.00034885116 | H34: 0.00035163589 | I34: 0.00071756135 | J34: 0.00029982661 | K34: 0.00016626612 | L34: 0.00010964488 | M34: 0.00015814673 | N34: 0.00034762467 | O34: 0.00011911976 | P34: 0.00014301282 | Q34: 7.7393236e-05 | R34: 0.00036897933 | S34: 0.00010505127 | T34: 0.00018729356 | U34: 0.00024276934 | V34: 0.00014022595 | W34: 0.00011386703
B35: BSE.NS | C35: 0.00025799368 | D35: 9.3597403e-05 | E35: 0.0001132721 | F35: 9.4660529e-05 | G35: 0.0002516801 | H35: 0.00019598511 | I35: 0.00029982661 | J35: 0.0011174551 | K35: 0.00014723953 | L35: 0.00013483184 | M35: 0.00014753881 | N35: 0.00019385531 | O35: 0.00010728542 | P35: 0.00014414608 | Q35: 6.3953655e-05 | R35: 0.00023189994 | S35: 7.4017421e-05 | T35: 0.00012209756 | U35: 0.00019406829 | V35: 0.00013231751 | W35: 8.7943571e-05
B36: CHOLAFIN.NS | C36: 0.00016930572 | D36: 0.00012089666 | E36: 0.00010768479 | F36: 0.00016207753 | G36: 0.00012538019 | H36: 0.00012643018 | I36: 0.00016626612 | J36: 0.00014723953 | K36: 0.0004146775 | L36: 0.0001116278 | M36: 0.00011035291 | N36: 0.00013146476 | O36: 0.00010718496 | P36: 0.00013449901 | Q36: 4.2145537e-05 | R36: 0.00014866021 | S36: 7.2150571e-05 | T36: 0.00011376942 | U36: 0.00026169907 | V36: 0.00013366124 | W36: 8.9093454e-05
B37: EICHERMOT.NS | C37: 0.00013580208 | D37: 8.7649373e-05 | E37: 0.00010866322 | F37: 8.2670571e-05 | G37: 0.00010217958 | H37: 9.2397382e-05 | I37: 0.00010964488 | J37: 0.00013483184 | K37: 0.0001116278 | L37: 0.00026812771 | M37: 8.1044848e-05 | N37: 8.7038619e-05 | O37: 0.00010474502 | P37: 0.00013436837 | Q37: 2.6013042e-05 | R37: 0.00011796724 | S37: 5.1748424e-05 | T37: 8.7695679e-05 | U37: 0.00014754422 | V37: 0.00014679855 | W37: 7.3843825e-05
B38: FEDERALBNK.NS | C38: 0.00013298746 | D38: 8.5182389e-05 | E38: 6.614743e-05 | F38: 7.3847929e-05 | G38: 9.4487363e-05 | H38: 0.00011726531 | I38: 0.00015814673 | J38: 0.00014753881 | K38: 0.00011035291 | L38: 8.1044848e-05 | M38: 0.00026200662 | N38: 0.00011530506 | O38: 7.2743502e-05 | P38: 8.6521579e-05 | Q38: 2.2048715e-05 | R38: 0.00013384434 | S38: 4.2692372e-05 | T38: 0.00011686571 | U38: 0.00013119497 | V38: 6.7954707e-05 | W38: 6.1639876e-05
B39: HAL.NS | C39: 0.00023592716 | D39: 0.0001011663 | E39: 9.5450516e-05 | F39: 8.4406564e-05 | G39: 0.000426153 | H39: 0.00034444793 | I39: 0.00034762467 | J39: 0.00019385531 | K39: 0.00013146476 | L39: 8.7038619e-05 | M39: 0.00011530506 | N39: 0.00048635217 | O39: 9.085851e-05 | P39: 0.00011711383 | Q39: 5.1337089e-05 | R39: 0.00042426735 | S39: 8.3501184e-05 | T39: 0.00015008168 | U39: 0.0001847004 | V39: 0.00012067938 | W39: 9.0421139e-05
B40: HEROMOTOCO.NS | C40: 0.00012704605 | D40: 6.3269554e-05 | E40: 0.00014541174 | F40: 8.2055292e-05 | G40: 9.5459928e-05 | H40: 7.7897508e-05 | I40: 0.00011911976 | J40: 0.00010728542 | K40: 0.00010718496 | L40: 0.00010474502 | M40: 7.2743502e-05 | N40: 9.085851e-05 | O40: 0.00027480887 | P40: 0.00013025576 | Q40: 2.0276624e-05 | R40: 0.00010156989 | S40: 4.2362432e-05 | T40: 5.9662601e-05 | U40: 0.00012650311 | V40: 0.00014809291 | W40: 6.488899e-05
... B48: ^NSEI | C48: 0.00011888742 | D48: 7.708398e-05 | E48: 6.1451726e-05 | F48: 7.8114511e-05 | G48: 8.5720328e-05 | H48: 9.0746235e-05 | I48: 0.00011386703 | J48: 8.7943571e-05 | K48: 8.9093454e-05 | L48: 7.3843825e-05 | M48: 6.1639876e-05 | N48: 9.0421139e-05 | O48: 6.488899e-05 | P48: 9.1791462e-05 | Q48: 2.4736166e-05 | R48: 0.00010074289 | S48: 4.4939645e-05 | T48: 8.1777503e-05 | U48: 0.00011483398 | V48: 7.3908537e-05 | W48: 6.9076912e-05
C50: For Equally weighted Portfolio
D51: ADANIGREEN.NS | E51: AXISBANK.NS | F51: BAJAJ-AUTO.NS | G51: BAJAJFINSV.NS | H51: BDL.NS | I51: BEL.NS | J51: BHEL.NS | K51: BSE.NS | L51: CHOLAFIN.NS | M51: EICHERMOT.NS | N51: FEDERALBNK.NS | O51: HAL.NS | P51: HEROMOTOCO.NS | Q51: M&M.NS | R51: MAFANG.NS | S51: MAZDOCK.NS | T51: MON100.NS | U51: SBIN.NS | V51: SHRIRAMFIN.NS | W51: TVSMOTOR.NS
A52: Daily Variance | B52: σ_p^2 | C52: {=MMULT(MMULT(D58:W58,C28:V47),TRANSPOSE(D58:W58))} -> 0.00036651334
A53: Daily Std Dev | B53: σ_p | C53: =SQRT(C52) -> 0.019144538
A54: Annual Std Dev | B54: σ_p (Annual) | C54: =C53*SQRT(252) -> 0.30391012
...

Sheet Tobin Sep
C2: Covariance Matrix Σ=X'X/(n-1)
C3: ADANIGREEN.NS | D3: AXISBANK.NS | E3: BAJAJ-AUTO.NS | F3: BAJAJFINSV.NS | G3: BDL.NS | H3: BEL.NS | I3: BHEL.NS | J3: BSE.NS | K3: CHOLAFIN.NS | L3: EICHERMOT.NS | M3: FEDERALBNK.NS | N3: HAL.NS | O3: HEROMOTOCO.NS | P3: M&M.NS | Q3: MAFANG.NS | R3: MAZDOCK.NS | S3: MON100.NS | T3: SBIN.NS | U3: SHRIRAMFIN.NS | V3: TVSMOTOR.NS
B4: ADANIGREEN.NS | C4: 0.0009902409 | D4: 0.00013539385 | E4: 0.00012328423 | F4: 0.00013727421 | G4: 0.00022658088 | H4: 0.00023258727 | I4: 0.00029903878 | J4: 0.00025799368 | K4: 0.00016930572 | L4: 0.00013580208 | M4: 0.00013298746 | N4: 0.00023592716 | O4: 0.00012704605 | P4: 0.00014546867 | Q4: 4.8022748e-05 | R4: 0.0002899962 | S4: 8.6647181e-05 | T4: 0.00016878589 | U4: 0.00021761183 | V4: 0.00015577431
B5: AXISBANK.NS | C5: 0.00013539385 | D5: 0.00021722309 | E5: 6.8757525e-05 | F5: 9.8277292e-05 | G5: 8.225993e-05 | H5: 9.3643616e-05 | I5: 0.00012248037 | J5: 9.3597403e-05 | K5: 0.00012089666 | L5: 8.7649373e-05 | M5: 8.5182389e-05 | N5: 0.0001011663 | O5: 6.3269554e-05 | P5: 8.8721653e-05 | Q5: 1.6606027e-05 | R5: 0.00013257864 | S5: 3.820464e-05 | T5: 0.00011417541 | U5: 0.00016038867 | V5: 9.1744334e-05
B6: BAJAJ-AUTO.NS | C6: 0.00012328423 | D6: 6.8757525e-05 | E6: 0.00025501447 | F6: 7.1296308e-05 | G6: 0.00010021514 | H6: 8.2818873e-05 | I6: 0.00012210702 | J6: 0.0001132721 | K6: 0.00010768479 | L6: 0.00010866322 | M6: 6.614743e-05 | N6: 9.5450516e-05 | O6: 0.00014541174 | P6: 0.00012177026 | Q6: 2.0993219e-05 | R6: 0.00011665432 | S6: 4.9141482e-05 | T6: 5.9561289e-05 | U6: 0.00012621707 | V6: 0.00013708992
B7: BAJAJFINSV.NS | C7: 0.00013727421 | D7: 9.8277292e-05 | E7: 7.1296308e-05 | F7: 0.00021835284 | G7: 7.0899602e-05 | H7: 8.0655377e-05 | I7: 0.00010792578 | J7: 9.4660529e-05 | K7: 0.00016207753 | L7: 8.2670571e-05 | M7: 7.3847929e-05 | N7: 8.4406564e-05 | O7: 8.2055292e-05 | P7: 0.00011359013 | Q7: 1.9884546e-05 | R7: 7.9728302e-05 | S7: 5.1777297e-05 | T7: 9.1850116e-05 | U7: 0.00016591692 | V7: 9.1002388e-05
B8: BDL.NS | C8: 0.00022658088 | D8: 8.225993e-05 | E8: 0.00010021514 | F8: 7.0899602e-05 | G8: 0.0008293993 | H8: 0.00037342764 | I8: 0.00034885116 | J8: 0.0002516801 | K8: 0.00012538019 | L8: 0.00010217958 | M8: 9.4487363e-05 | N8: 0.000426153 | O8: 9.5459928e-05 | P8: 0.00011536142 | Q8: 5.5067169e-05 | R8: 0.00057799882 | S8: 9.5597514e-05 | T8: 0.00014328343 | U8: 0.00018106204 | V8: 0.00012610932
B9: BEL.NS | C9: 0.00023258727 | D9: 9.3643616e-05 | E9: 8.2818873e-05 | F9: 8.0655377e-05 | G9: 0.00037342764 | H9: 0.00042565653 | I9: 0.00035163589 | J9: 0.00019598511 | K9: 0.00012643018 | L9: 9.2397382e-05 | M9: 0.00011726531 | N9: 0.00034444793 | O9: 7.7897508e-05 | P9: 0.00012466323 | Q9: 5.7651277e-05 | R9: 0.00037927598 | S9: 7.5614856e-05 | T9: 0.00015447995 | U9: 0.00018165495 | V9: 0.00010422338
B10: BHEL.NS | C10: 0.00029903878 | D10: 0.00012248037 | E10: 0.00012210702 | F10: 0.00010792578 | G10: 0.00034885116 | H10: 0.00035163589 | I10: 0.00071756135 | J10: 0.00029982661 | K10: 0.00016626612 | L10: 0.00010964488 | M10: 0.00015814673 | N10: 0.00034762467 | O10: 0.00011911976 | P10: 0.00014301282 | Q10: 7.7393236e-05 | R10: 0.00036897933 | S10: 0.00010505127 | T10: 0.00018729356 | U10: 0.00024276934 | V10: 0.00014022595
B11: BSE.NS | C11: 0.00025799368 | D11: 9.3597403e-05 | E11: 0.0001132721 | F11: 9.4660529e-05 | G11: 0.0002516801 | H11: 0.00019598511 | I11: 0.00029982661 | J11: 0.0011174551 | K11: 0.00014723953 | L11: 0.00013483184 | M11: 0.00014753881 | N11: 0.00019385531 | O11: 0.00010728542 | P11: 0.00014414608 | Q11: 6.3953655e-05 | R11: 0.00023189994 | S11: 7.4017421e-05 | T11: 0.00012209756 | U11: 0.00019406829 | V11: 0.00013231751
B12: CHOLAFIN.NS | C12: 0.00016930572 | D12: 0.00012089666 | E12: 0.00010768479 | F12: 0.00016207753 | G12: 0.00012538019 | H12: 0.00012643018 | I12: 0.00016626612 | J12: 0.00014723953 | K12: 0.0004146775 | L12: 0.0001116278 | M12: 0.00011035291 | N12: 0.00013146476 | O12: 0.00010718496 | P12: 0.00013449901 | Q12: 4.2145537e-05 | R12: 0.00014866021 | S12: 7.2150571e-05 | T12: 0.00011376942 | U12: 0.00026169907 | V12: 0.00013366124
B13: EICHERMOT.NS | C13: 0.00013580208 | D13: 8.7649373e-05 | E13: 0.00010866322 | F13: 8.2670571e-05 | G13: 0.00010217958 | H13: 9.2397382e-05 | I13: 0.00010964488 | J13: 0.00013483184 | K13: 0.0001116278 | L13: 0.00026812771 | M13: 8.1044848e-05 | N13: 8.7038619e-05 | O13: 0.00010474502 | P13: 0.00013436837 | Q13: 2.6013042e-05 | R13: 0.00011796724 | S13: 5.1748424e-05 | T13: 8.7695679e-05 | U13: 0.00014754422 | V13: 0.00014679855
B14: FEDERALBNK.NS | C14: 0.00013298746 | D14: 8.5182389e-05 | E14: 6.614743e-05 | F14: 7.3847929e-05 | G14: 9.4487363e-05 | H14: 0.00011726531 | I14: 0.00015814673 | J14: 0.00014753881 | K14: 0.00011035291 | L14: 8.1044848e-05 | M14: 0.00026200662 | N14: 0.00011530506 | O14: 7.2743502e-05 | P14: 8.6521579e-05 | Q14: 2.2048715e-05 | R14: 0.00013384434 | S14: 4.2692372e-05 | T14: 0.00011686571 | U14: 0.00013119497 | V14: 6.7954707e-05
B15: HAL.NS | C15: 0.00023592716 | D15: 0.0001011663 | E15: 9.5450516e-05 | F15: 8.4406564e-05 | G15: 0.000426153 | H15: 0.00034444793 | I15: 0.00034762467 | J15: 0.00019385531 | K15: 0.00013146476 | L15: 8.7038619e-05 | M15: 0.00011530506 | N15: 0.00048635217 | O15: 9.085851e-05 | P15: 0.00011711383 | Q15: 5.1337089e-05 | R15: 0.00042426735 | S15: 8.3501184e-05 | T15: 0.00015008168 | U15: 0.0001847004 | V15: 0.00012067938
... B23: TVSMOTOR.NS | C23: 0.00015577431 | D23: 9.1744334e-05 | E23: 0.00013708992 | F23: 9.1002388e-05 | G23: 0.00012610932 | H23: 0.00010422338 | I23: 0.00014022595 | J23: 0.00013231751 | K23: 0.00013366124 | L23: 0.00014679855 | M23: 6.7954707e-05 | N23: 0.00012067938 | O23: 0.00014809291 | P23: 0.00016692725 | Q23: 2.5094676e-05 | R23: 0.00013400716 | S23: 5.9035082e-05 | T23: 8.3943793e-05 | U23: 0.00016568442 | V23: 0.00028417779
C26: Inverse Covariance Matrix Σ^-1
C27: ADANIGREEN.NS | D27: AXISBANK.NS | E27: BAJAJ-AUTO.NS | F27: BAJAJFINSV.NS | G27: BDL.NS | H27: BEL.NS | I27: BHEL.NS | J27: BSE.NS | K27: CHOLAFIN.NS | L27: EICHERMOT.NS | M27: FEDERALBNK.NS | N27: HAL.NS | O27: HEROMOTOCO.NS | P27: M&M.NS | Q27: MAFANG.NS | R27: MAZDOCK.NS | S27: MON100.NS | T27: SBIN.NS | U27: SHRIRAMFIN.NS | V27: TVSMOTOR.NS | X27: Once Vector | Z27: Exp. Return
B28: {=TRANSPOSE(C27:V27)} -> ADANIGREEN.NS | C28: {=MINVERSE(C4:V23)} -> 1318.2058 | D28: -123.29115 | E28: -61.419125 | F28: -257.56998 | G28: 66.997163 | H28: -183.1298 | I28: -143.70522 | J28: -101.98521 | K28: -10.332559 | L28: -86.079583 | M28: -35.288891 | N28: -96.323903 | O28: -96.822664 | P28: 48.506854 | Q28: 2.8027747 | R28: -86.240886 | S28: -108.38936 | T28: -258.30546 | U28: -7.2002045 | V28: -150.7718 | X28: 1 | Z28: 0.0016649749
B29: AXISBANK.NS | C29: -123.29115 | D29: 7582.2864 | E29: -257.79211 | F29: -1271.7633 | G29: 325.57076 | H29: 228.17852 | I29: 9.7317979 | J29: 38.399449 | K29: -261.10337 | L29: -499.02777 | M29: -443.20912 | N29: -258.41986 | O29: 250.07406 | P29: 54.108526 | Q29: -81.979608 | R29: -310.59818 | S29: 161.23587 | T29: -1825.7515 | U29: -794.09494 | V29: -542.80193 | X29: 1 | Z29: 0.00053674185
B30: BAJAJ-AUTO.NS | C30: -61.419125 | D30: -257.79211 | E30: 6586.2813 | F30: 120.26357 | G30: -16.918383 | H30: 171.50627 | I30: -185.48465 | J30: -61.037252 | K30: -262.25718 | L30: -683.89888 | M30: -126.4526 | N30: -142.72348 | O30: -2100.023 | P30: -442.067 | Q30: 108.43793 | R30: -74.91851 | S30: -371.00946 | T30: 344.5514 | U30: -118.67334 | V30: -1042.5734 | X30: 1 | Z30: 0.0011908984
B31: BAJAJFINSV.NS | C31: -257.56998 | D31: -1271.7633 | E31: 120.26357 | F31: 8043.5707 | G31: 49.307549 | H31: 146.73982 | I31: 93.023383 | J31: 14.238063 | K31: -1642.3767 | L31: -104.3048 | M31: -31.007405 | N31: -102.42591 | O31: -569.92113 | P31: -1024.2803 | Q31: 121.56254 | R31: 270.77173 | S31: -722.45439 | T31: -720.58281 | U31: -741.99915 | V31: 222.79131 | X31: 1 | Z31: 0.00032898822
B32: BDL.NS | C32: 66.997163 | D32: 325.57076 | E32: -16.918383 | F32: 49.307549 | G32: 2688.0471 | H32: -828.24011 | I32: 18.12771 | J32: -164.35409 | K32: -15.560365 | L32: -137.148 | M32: 318.72212 | N32: -1226.2509 | O32: -104.97352 | P32: 182.96162 | Q32: 105.03381 | R32: -674.33222 | S32: -298.15948 | T32: -53.383663 | U32: 28.134647 | V32: -131.04867 | X32: 1 | Z32: 0.0017297863
B33: BEL.NS | C33: -183.1298 | D33: 228.17852 | E33: 171.50627 | F33: 146.73982 | G33: -828.24011 | H33: 7177.139 | I33: -1201.6738 | J33: 10.407435 | K33: -26.658336 | L33: -206.84787 | M33: -247.70778 | N33: -2747.0966 | O33: 253.34368 | P33: -586.8858 | Q33: -413.2531 | R33: -314.6426 | S33: 159.32001 | T33: -929.94374 | U33: -210.04762 | V33: 327.26351 | X33: 1 | Z33: 0.002505841
B34: BHEL.NS | C34: -143.70522 | D34: 9.7317979 | E34: -185.48465 | F34: 93.023383 | G34: 18.12771 | H34: -1201.6738 | I34: 2767.1374 | J34: -235.92508 | K34: 30.129393 | L34: 237.03444 | M34: -280.2833 | N34: -566.47478 | O34: -168.39883 | P34: 67.24575 | Q34: -227.69492 | R34: -18.127842 | S34: -319.1653 | T34: -459.95602 | U34: -287.24975 | V34: -70.057056 | X34: 1 | Z34: 0.003829447
B35: BSE.NS | C35: -101.98521 | D35: 38.399449 | E35: -61.037252 | F35: 14.238063 | G35: -164.35409 | H35: 10.407435 | I35: -235.92508 | J35: 1094.6342 | K35: -27.562027 | L35: -168.99363 | M35: -278.53469 | N35: 58.80688 | O35: 15.539079 | P35: -103.76143 | Q35: -126.28441 | R35: 22.323415 | S35: 29.389384 | T35: 48.893828 | U35: -81.835091 | V35: -33.217111 | X35: 1 | Z35: 0.0058852828
B36: CHOLAFIN.NS | C36: -10.332559 | D36: -261.10337 | E36: -262.25718 | F36: -1642.3767 | G36: -15.560365 | H36: -26.658336 | I36: 30.129393 | J36: -27.562027 | K36: 4306.6406 | L36: 31.628223 | M36: -395.6852 | N36: -22.500859 | O36: -39.456429 | P36: -72.331344 | Q36: -350.56245 | R36: 3.0569572 | S36: -220.22213 | T36: 75.004459 | U36: -1266.432 | V36: -326.1766 | X36: 1 | Z36: 0.00082799882
B37: EICHERMOT.NS | C37: -86.079583 | D37: -499.02777 | E37: -683.89888 | F37: -104.3048 | G37: -137.148 | H37: -206.84787 | I37: 237.03444 | J37: -168.99363 | K37: 31.628223 | L37: 6068.5986 | M37: -420.1021 | N37: 436.61282 | O37: -219.44788 | P37: -658.44152 | Q37: -128.24465 | R37: -22.364227 | S37: -298.07333 | T37: -468.51951 | U37: -356.8092 | V37: -1633.2929 | X37: 1 | Z37: 0.001128739
B38: FEDERALBNK.NS | C38: -35.288891 | D38: -443.20912 | E38: -126.4526 | F38: -31.007405 | G38: 318.72212 | H38: -247.70778 | I38: -280.2833 | J38: -278.53469 | K38: -395.6852 | L38: -420.1021 | M38: 5554.022 | N38: -187.92506 | O38: -495.48422 | P38: -162.29811 | Q38: 47.065494 | R38: -94.67876 | S38: -169.9442 | T38: -1493.1325 | U38: -78.940171 | V38: 521.9951 | X38: 1 | Z38: 0.0012282551
B39: HAL.NS | C39: -96.323903 | D39: -258.41986 | E39: -142.72348 | F39: -102.42591 | G39: -1226.2509 | H39: -2747.0966 | I39: -566.47478 | J39: 58.80688 | K39: -22.500859 | L39: 436.61282 | M39: -187.92506 | N39: 6184.886 | O39: -76.866931 | P39: 165.08491 | Q39: 83.410881 | R39: -448.20656 | S39: -293.94955 | T39: -264.98124 | U39: -13.836056 | V39: -460.3182 | X39: 1 | Z39: 0.0019796446
B40: HEROMOTOCO.NS | C40: -96.822664 | D40: 250.07406 | E40: -2100.023 | F40: -569.92113 | G40: -104.97352 | H40: 253.34368 | I40: -168.39883 | J40: 15.539079 | K40: -39.456429 | L40: -219.44788 | M40: -495.48422 | N40: -76.866931 | O40: 6208.87 | P40: -535.62301 | Q40: -53.711557 | R40: 45.986206 | S40: 188.18644 | T40: 310.25794 | U40: -95.072108 | V40: -1532.75 | X40: 1 | Z40: 0.00093926843
... B47: TVSMOTOR.NS | C47: -150.7718 | D47: -542.80193 | E47: -1042.5734 | F47: 222.79131 | G47: -131.04867 | H47: 327.26351 | I47: -70.057056 | J47: -33.217111 | K47: -326.1766 | L47: -1633.2929 | M47: 521.9951 | N47: -460.3182 | O47: -1532.75 | P47: -1458.8186 | Q47: 86.551791 | R47: 102.76363 | S47: -390.46576 | T47: -5.4503178 | U47: -428.46933 | V47: 7196.4719 | X47: 1 | Z47: 0.0015507035
C50: Baseline weight [g] | D50: h1 | E50: h2 | F50: Return Escalating weight h=h1-h2 | G50: c | H50: w=g+(c*h)
B51: ADANIGREEN.NS | C51: {=MMULT(_xlfn.ANCHORARRAY(C28),X28:X47)/SUM(MMULT(_xlfn.ANCHORARRAY(C28),X28:X47))} -> -0.026358971 | D51: {=MMULT(_xlfn.ANCHORARRAY(C28),Z28:Z47)} -> -0.84490849 | E51: {=(SUM(_xlfn.ANCHORARRAY(D51))/SUM(MMULT(_xlfn.ANCHORARRAY(C28),X28:X47)))*(MMULT(_xlfn.ANCHORARRAY(C28),X28:X47))} -> -0.20215956 | F51: =D51-E51 -> -0.64274893 | G51: -0.0018221622 | H51: =C51+(G51*F51) -> -0.025187779
B52: AXISBANK.NS | C52: 0.14090779 | D52: -3.1853651 | E52: 1.0806893 | F52: =D52-E52 -> -4.2660543 | G52: =G51 -> -0.0018221622 | H52: =C52+(G52*F52) -> 0.14868124
B53: BAJAJ-AUTO.NS | C53: 0.098490644 | D53: 0.6199844 | E53: 0.75537187 | F53: =D53-E53 -> -0.13538747 | G53: =G52 -> -0.0018221622 | H53: =C53+(G53*F53) -> 0.098737342
B54: BAJAJFINSV.NS | C54: 0.13477471 | D54: -3.6159768 | E54: 1.0336517 | F54: =D54-E54 -> -4.6496285 | G54: =G53 -> -0.0018221622 | H54: =C54+(G54*F54) -> 0.14324709
B55: BDL.NS | C55: 0.0094329688 | D55: -3.0934452 | E55: 0.072345951 | F55: =D55-E55 -> -3.1657912 | G55: =G54 -> -0.0018221622 | H55: =C55+(G55*F55) -> 0.015201554
B56: BEL.NS | C56: 0.041122532 | D56: 2.9286036 | E56: 0.31538838 | F56: =D56-E56 -> 2.6132153 | G56: =G55 -> -0.0018221622 | H56: =C56+(G56*F56) -> 0.03636083
B57: BHEL.NS | C57: -0.067029724 | D57: 2.5180403 | E57: -0.51408302 | F57: =D57-E57 -> 3.0321233 | G57: =G56 -> -0.0018221622 | H57: =C57+(G57*F57) -> -0.072554745
B58: BSE.NS | C58: -0.0036198092 | D58: 4.2359322 | E58: -0.027762048 | F58: =D58-E58 -> 4.2636942 | G58: =G57 -> -0.0018221622 | H58: =C58+(G58*F58) -> -0.011388951
...
